Workbook

Sheet README
A1: IP First Response: AI referral and citation analysis
A2: Built 11 Sep 2026 from three exports. Every figure below is a live formula over the Sessions, Pages and Daily tabs, so filtering or correcting a source row reflows the whole workbook.
A5: Headline numbers
A6: Bing AI citations (by page) | B6: =Pages!E106 -> 9202
A7: Sessions from AI assistants | B7: =Pages!F106 -> 443
A8: Overall CTR, all AI referrers | B8: =IFERROR(Pages!F106/Pages!E106,"") -> 0.048141708
A9: Overall CTR, Copilot sessions only | B9: =IFERROR(Pages!J106/Pages!E106,"") -> 0.00032601608
A10: Same CTR using the daily citation total | B10: =IFERROR(Pages!F106/Daily!H$123,"") -> 0.042331581
A11: Pages cited by Bing AI | B11: =COUNTIF(Pages!O2:O105,"cited*") -> 88
A12: Pages with AI referral landings | B12: =COUNTIF(Pages!O2:O105,"*landed")+COUNTIF(Pages!O2:O105,"landings*") -> 75
A14: What each tab holds
A15: README | B15: This page. Definitions, join logic and the caveats that change how the numbers should be read.
A16: Pages | B16: One row per canonical URL, outer joined across both sources. This is the CTR-per-page view. The totals row uses SUBTOTAL, so filter by section or match status and the CTR at the bottom recalculates for that slice.
A17: Daily | B17: One row per calendar day across the full union of both date ranges, with citations, sessions and CTR. Date parts are pre-split into year, month, ISO week and weekday so no date maths is needed to pivot.
A18: Weekly | B18: ISO weeks, Monday start, rolled up from Daily with SUMIFS.
A19: Referrers | B19: Sessions by assistant.
A20: Sessions | B20: The cleaned Mixpanel extract at page-by-day-by-referrer grain. Raw landing URL is kept next to the canonical one so any normalisation can be audited.
A22: How the sources were joined
A23: Join key | B23: Canonical URL: scheme and host lowercased, query string and fragment removed, trailing slash stripped. Host is retained, so the chat subdomain stays a separate page.
A24: Why that matters | B24: Mixpanel landing URLs carry utm_source, _gl, utm_content and fragment noise, and several are truncated mid-parameter. Bing reports clean URLs. Without normalisation roughly a third of ChatGPT landings would not have matched their own Bing row.
A25: Grain limits | B25: Bing gives citations by day OR by page, never both at once. So page-level CTR has no time dimension and daily CTR has no page dimension. A page-by-day citation figure cannot be derived from these exports and is not in this workbook.
A27: Read these before quoting a CTR
A28: The numerator and denominator are different populations | B28: Bing's AI Performance report counts citations in Microsoft Copilot, Bing AI summaries and its partner integrations. The Mixpanel sessions are overwhelmingly ChatGPT. Treat the headline CTR as a rough visibility-to-traffic yield, not a real click-through rate. The Copilot-only CTR is the apples-to-apples version, but it rests on very few sessions.
A29: The two Bing exports do not reconcile | B29: Citations summed by day and citations summed by page differ by about 12 percent. Same report, same nominal window, different totals. Worth checking whether the per-page export is capped or truncated before either number goes in a deck.
A30: One day is an outlier | B30: 30 July 2026 records roughly six times the typical daily citation count. It moves both the monthly and the all-period CTR. Decide whether to keep or exclude it before reporting a trend.
A31: Date ranges differ | B31: Bing daily data runs 14 May to 8 Sep 2026. Mixpanel sessions run 15 May to 11 Sep 2026. The Daily tab spans the union and flags each day in the source coverage column. Filter to 'both' before comparing the two series.
A32: Sessions are first-touch only | B32: Mixpanel reports the initial referrer and the landing page of the session. A user who arrives from ChatGPT and then reads four more pages counts once, against the first page.
A33: Truncated links produce 404s | B33: Two ChatGPT landings hit a URL cut off mid-slug and served the 404 page. Small volume, but it points at links being emitted with a malformed path.
A35: Two ways to average a CTR
A36: Weekly totals (Weekly column K) | B36: Total sessions for the week divided by total citations for the week. High-citation days dominate. Use this when the question is about aggregate yield.
A37: Mean of daily CTRs (Weekly column L) | B37: Each day weighted equally regardless of volume. Use this when the question is about a typical day. The two diverge whenever daily volume is uneven, which here it is.

Sheet Sessions
A1: date | B1: referrer | C1: page_title | D1: canonical_url | E1: path | F1: section | G1: raw_landing_url | H1: had_tracking_params | I1: sessions | J1: first row for page+date
A2: 46157 | B2: Claude | C2: Unregistered trade marks | D2: https://ipfirstresponse.ipaustralia.gov.au/options/infringement-101-unregistered-trade-marks | E2: /options/infringement-101-unregistered-trade-marks | F2: options | G2: https://ipfirstresponse.ipaustralia.gov.au/options/infringement-101-unregistered-trade-marks | H2: no | I2: 1 | J2: =IF(COUNTIFS($D$2:$D2,$D2,$A$2:$A2,$A2)=1,1,0) -> 1
A3: 46158 | B3: ChatGPT | C3: Considerations when using artificial intelligence to create IP | D3: https://ipfirstresponse.ipaustralia.gov.au/options/considerations-when-using-artificial-intelligence-create-ip-0 | E3: /options/considerations-when-using-artificial-intelligence-create-ip-0 | F3: options | G3: https://ipfirstresponse.ipaustralia.gov.au/options/considerations-when-using-artificial-intelligence-create-ip-0 | H3: no | I3: 1 | J3: =IF(COUNTIFS($D$2:$D3,$D3,$A$2:$A3,$A3)=1,1,0) -> 1
A4: 46160 | B4: Claude | C4: Register your trade mark | D4: https://ipfirstresponse.ipaustralia.gov.au/options/register-your-trade-mark | E4: /options/register-your-trade-mark | F4: options | G4: https://ipfirstresponse.ipaustralia.gov.au/options/register-your-trade-mark | H4: no | I4: 1 | J4: =IF(COUNTIFS($D$2:$D4,$D4,$A$2:$A4,$A4)=1,1,0) -> 1
A5: 46161 | B5: ChatGPT | C5: Design infringement | D5: https://ipfirstresponse.ipaustralia.gov.au/options/infringement-101-design-infringement | E5: /options/infringement-101-design-infringement | F5: options | G5: https://ipfirstresponse.ipaustralia.gov.au/options/infringement-101-design-infringement?utm_ | H5: yes | I5: 1 | J5: =IF(COUNTIFS($D$2:$D5,$D5,$A$2:$A5,$A5)=1,1,0) -> 1
A6: 46161 | B6: ChatGPT | C6: Design infringement | D6: https://ipfirstresponse.ipaustralia.gov.au/options/infringement-101-design-infringement | E6: /options/infringement-101-design-infringement | F6: options | G6: https://ipfirstresponse.ipaustralia.gov.au/options/infringement-101-design-infringement?utm_source=chatgpt.com | H6: yes | I6: 1 | J6: =IF(COUNTIFS($D$2:$D6,$D6,$A$2:$A6,$A6)=1,1,0) -> 0
A7: 46162 | B7: ChatGPT | C7: Unregistered trade marks | D7: https://ipfirstresponse.ipaustralia.gov.au/options/infringement-101-unregistered-trade-marks | E7: /options/infringement-101-unregistered-trade-marks | F7: options | G7: https://ipfirstresponse.ipaustralia.gov.au/options/infringement-101-unregistered-trade-marks?utm_source=chatgpt.com | H7: yes | I7: 1 | J7: =IF(COUNTIFS($D$2:$D7,$D7,$A$2:$A7,$A7)=1,1,0) -> 1
A8: 46162 | B8: ChatGPT | C8: Unregistered trade marks | D8: https://ipfirstresponse.ipaustralia.gov.au/options/infringement-101-unregistered-trade-marks | E8: /options/infringement-101-unregistered-trade-marks | F8: options | G8: https://ipfirstresponse.ipaustralia.gov.au/options/infringement-101-unregistered-trade-marks | H8: no | I8: 1 | J8: =IF(COUNTIFS($D$2:$D8,$D8,$A$2:$A8,$A8)=1,1,0) -> 0
A9: 46163 | B9: ChatGPT | C9: Is my business name my IP? | D9: https://ipfirstresponse.ipaustralia.gov.au/options/my-business-name-my-ip | E9: /options/my-business-name-my-ip | F9: options | G9: https://ipfirstresponse.ipaustralia.gov.au/options/my-business-name-my-ip?utm_source=chatgpt.com | H9: yes | I9: 2 | J9: =IF(COUNTIFS($D$2:$D9,$D9,$A$2:$A9,$A9)=1,1,0) -> 1
A10: 46163 | B10: ChatGPT | C10: Stop infringing goods entering the country | D10: https://ipfirstresponse.ipaustralia.gov.au/options/stop-infringing-goods-entering-country | E10: /options/stop-infringing-goods-entering-country | F10: options | G10: https://ipfirstresponse.ipaustralia.gov.au/options/stop-infringing-goods-entering-country?utm_source=chatgpt.com | H10: yes | I10: 1 | J10: =IF(COUNTIFS($D$2:$D10,$D10,$A$2:$A10,$A10)=1,1,0) -> 1
A11: 46164 | B11: Copilot | C11: Challenge a new or amended patent | D11: https://ipfirstresponse.ipaustralia.gov.au/options/challenge-new-or-amended-patent | E11: /options/challenge-new-or-amended-patent | F11: options | G11: https://ipfirstresponse.ipaustralia.gov.au/options/challenge-new-or-amended-patent?utm_source=copilot.com | H11: yes | I11: 1 | J11: =IF(COUNTIFS($D$2:$D11,$D11,$A$2:$A11,$A11)=1,1,0) -> 1
A12: 46164 | B12: ChatGPT | C12: Tips and tricks for searching for an existing right | D12: https://ipfirstresponse.ipaustralia.gov.au/tips-and-tricks-searching-existing-right | E12: /tips-and-tricks-searching-existing-right | F12: (top level) | G12: https://ipfirstresponse.ipaustralia.gov.au/tips-and-tricks-searching-existing-right | H12: no | I12: 1 | J12: =IF(COUNTIFS($D$2:$D12,$D12,$A$2:$A12,$A12)=1,1,0) -> 1
A13: 46167 | B13: Claude | C13: Seek binding, authoritative decisions | D13: https://ipfirstresponse.ipaustralia.gov.au/options/court-patents | E13: /options/court-patents | F13: options | G13: https://ipfirstresponse.ipaustralia.gov.au/options/court-patents | H13: no | I13: 1 | J13: =IF(COUNTIFS($D$2:$D13,$D13,$A$2:$A13,$A13)=1,1,0) -> 1
... A405: 46276 | B405: ChatGPT | C405: Check if someone else already owns a word, logo or idea you want | D405: https://ipfirstresponse.ipaustralia.gov.au/options/check-if-someone-else-already-owns-word-logo-or-idea-you-want | E405: /options/check-if-someone-else-already-owns-word-logo-or-idea-you-want | F405: options | G405: https://ipfirstresponse.ipaustralia.gov.au/options/check-if-someone-else-already-owns-word-logo-or-idea-you-want?utm_source=chatgpt.com | H405: yes | I405: 1 | J405: =IF(COUNTIFS($D$2:$D405,$D405,$A$2:$A405,$A405)=1,1,0) -> 1
A407: Mixpanel emits one row per landing-URL variant, so the same page and date can appear twice (once with tracking parameters, once without). Column J marks the first row of each page-and-date pair, which is what the Pages tab counts as a day with sessions.

Sheet Pages
A1: canonical_url | B1: path | C1: section | D1: page_title | E1: citations (Bing AI) | F1: sessions (all AI referrers) | G1: ChatGPT | H1: Claude | I1: Gemini | J1: Copilot | K1: CTR all referrers | L1: CTR Copilot only | M1: share of citations | N1: share of sessions | O1: match status | P1: first session | Q1: last session | R1: days with sessions
A2: https://ipfirstresponse.ipaustralia.gov.au/options/infringement-101-copyright-infringement | B2: /options/infringement-101-copyright-infringement | C2: options | D2: Copyright infringement | E2: 2647 | F2: =SUMIFS(Sessions!$I:$I,Sessions!$D:$D,$A2) -> 25 | G2: =SUMIFS(Sessions!$I:$I,Sessions!$D:$D,$A2,Sessions!$B:$B,"ChatGPT") -> 25 | H2: =SUMIFS(Sessions!$I:$I,Sessions!$D:$D,$A2,Sessions!$B:$B,"Claude") -> 0 | I2: =SUMIFS(Sessions!$I:$I,Sessions!$D:$D,$A2,Sessions!$B:$B,"Gemini") -> 0 | J2: =SUMIFS(Sessions!$I:$I,Sessions!$D:$D,$A2,Sessions!$B:$B,"Copilot") -> 0 | K2: =IFERROR(F2/E2,"") -> 0.0094446543 | L2: =IFERROR(J2/E2,"") -> 0 | M2: =IFERROR(E2/$E$106,"") -> 0.28765486 | N2: =IFERROR(F2/$F$106,"") -> 0.056433409 | O2: cited and landed | P2: =IF(F2=0,"",_xlfn.MINIFS(Sessions!$A:$A,Sessions!$D:$D,$A2)) -> 46175 | Q2: =IF(F2=0,"",_xlfn.MAXIFS(Sessions!$A:$A,Sessions!$D:$D,$A2)) -> 46275 | R2: =SUMIFS(Sessions!$J:$J,Sessions!$D:$D,$A2) -> 21
A3: https://ipfirstresponse.ipaustralia.gov.au/blogs/copyright-licensing-and-rights-management-organisations-australia | B3: /blogs/copyright-licensing-and-rights-management-organisations-australia | C3: blogs | D3: Copyright licensing and rights management organisations in Australia | E3: 1425 | F3: =SUMIFS(Sessions!$I:$I,Sessions!$D:$D,$A3) -> 1 | G3: =SUMIFS(Sessions!$I:$I,Sessions!$D:$D,$A3,Sessions!$B:$B,"ChatGPT") -> 0 | H3: =SUMIFS(Sessions!$I:$I,Sessions!$D:$D,$A3,Sessions!$B:$B,"Claude") -> 1 | I3: =SUMIFS(Sessions!$I:$I,Sessions!$D:$D,$A3,Sessions!$B:$B,"Gemini") -> 0 | J3: =SUMIFS(Sessions!$I:$I,Sessions!$D:$D,$A3,Sessions!$B:$B,"Copilot") -> 0 | K3: =IFERROR(F3/E3,"") -> 0.00070175439 | L3: =IFERROR(J3/E3,"") -> 0 | M3: =IFERROR(E3/$E$106,"") -> 0.15485764 | N3: =IFERROR(F3/$F$106,"") -> 0.0022573363 | O3: cited and landed | P3: =IF(F3=0,"",_xlfn.MINIFS(Sessions!$A:$A,Sessions!$D:$D,$A3)) -> 46169 | Q3: =IF(F3=0,"",_xlfn.MAXIFS(Sessions!$A:$A,Sessions!$D:$D,$A3)) -> 46169 | R3: =SUMIFS(Sessions!$J:$J,Sessions!$D:$D,$A3) -> 1
A4: https://ipfirstresponse.ipaustralia.gov.au/blogs/simple-breakdown-names-and-trade-marks | B4: /blogs/simple-breakdown-names-and-trade-marks | C4: blogs | D4: A simple breakdown of names and trade marks | E4: 808 | F4: =SUMIFS(Sessions!$I:$I,Sessions!$D:$D,$A4) -> 18 | G4: =SUMIFS(Sessions!$I:$I,Sessions!$D:$D,$A4,Sessions!$B:$B,"ChatGPT") -> 18 | H4: =SUMIFS(Sessions!$I:$I,Sessions!$D:$D,$A4,Sessions!$B:$B,"Claude") -> 0 | I4: =SUMIFS(Sessions!$I:$I,Sessions!$D:$D,$A4,Sessions!$B:$B,"Gemini") -> 0 | J4: =SUMIFS(Sessions!$I:$I,Sessions!$D:$D,$A4,Sessions!$B:$B,"Copilot") -> 0 | K4: =IFERROR(F4/E4,"") -> 0.022277228 | L4: =IFERROR(J4/E4,"") -> 0 | M4: =IFERROR(E4/$E$106,"") -> 0.087806998 | N4: =IFERROR(F4/$F$106,"") -> 0.040632054 | O4: cited and landed | P4: =IF(F4=0,"",_xlfn.MINIFS(Sessions!$A:$A,Sessions!$D:$D,$A4)) -> 46180 | Q4: =IF(F4=0,"",_xlfn.MAXIFS(Sessions!$A:$A,Sessions!$D:$D,$A4)) -> 46275 | R4: =SUMIFS(Sessions!$J:$J,Sessions!$D:$D,$A4) -> 16
A5: https://ipfirstresponse.ipaustralia.gov.au/options/register-your-trade-mark | B5: /options/register-your-trade-mark | C5: options | D5: Register your trade mark | E5: 429 | F5: =SUMIFS(Sessions!$I:$I,Sessions!$D:$D,$A5) -> 19 | G5: =SUMIFS(Sessions!$I:$I,Sessions!$D:$D,$A5,Sessions!$B:$B,"ChatGPT") -> 15 | H5: =SUMIFS(Sessions!$I:$I,Sessions!$D:$D,$A5,Sessions!$B:$B,"Claude") -> 4 | I5: =SUMIFS(Sessions!$I:$I,Sessions!$D:$D,$A5,Sessions!$B:$B,"Gemini") -> 0 | J5: =SUMIFS(Sessions!$I:$I,Sessions!$D:$D,$A5,Sessions!$B:$B,"Copilot") -> 0 | K5: =IFERROR(F5/E5,"") -> 0.044289044 | L5: =IFERROR(J5/E5,"") -> 0 | M5: =IFERROR(E5/$E$106,"") -> 0.0466203 | N5: =IFERROR(F5/$F$106,"") -> 0.042889391 | O5: cited and landed | P5: =IF(F5=0,"",_xlfn.MINIFS(Sessions!$A:$A,Sessions!$D:$D,$A5)) -> 46160 | Q5: =IF(F5=0,"",_xlfn.MAXIFS(Sessions!$A:$A,Sessions!$D:$D,$A5)) -> 46269 | R5: =SUMIFS(Sessions!$J:$J,Sessions!$D:$D,$A5) -> 15
A6: https://ipfirstresponse.ipaustralia.gov.au/options/infringement-101-trade-mark-infringement | B6: /options/infringement-101-trade-mark-infringement | C6: options | D6: Trade mark infringement | E6: 329 | F6: =SUMIFS(Sessions!$I:$I,Sessions!$D:$D,$A6) -> 13 | G6: =SUMIFS(Sessions!$I:$I,Sessions!$D:$D,$A6,Sessions!$B:$B,"ChatGPT") -> 13 | H6: =SUMIFS(Sessions!$I:$I,Sessions!$D:$D,$A6,Sessions!$B:$B,"Claude") -> 0 | I6: =SUMIFS(Sessions!$I:$I,Sessions!$D:$D,$A6,Sessions!$B:$B,"Gemini") -> 0 | J6: =SUMIFS(Sessions!$I:$I,Sessions!$D:$D,$A6,Sessions!$B:$B,"Copilot") -> 0 | K6: =IFERROR(F6/E6,"") -> 0.039513678 | L6: =IFERROR(J6/E6,"") -> 0 | M6: =IFERROR(E6/$E$106,"") -> 0.035753097 | N6: =IFERROR(F6/$F$106,"") -> 0.029345372 | O6: cited and landed | P6: =IF(F6=0,"",_xlfn.MINIFS(Sessions!$A:$A,Sessions!$D:$D,$A6)) -> 46170 | Q6: =IF(F6=0,"",_xlfn.MAXIFS(Sessions!$A:$A,Sessions!$D:$D,$A6)) -> 46275 | R6: =SUMIFS(Sessions!$J:$J,Sessions!$D:$D,$A6) -> 13
A7: https://ipfirstresponse.ipaustralia.gov.au/options/infringement-101-what-ip-infringement | B7: /options/infringement-101-what-ip-infringement | C7: options | E7: 296 | F7: =SUMIFS(Sessions!$I:$I,Sessions!$D:$D,$A7) -> 0 | G7: =SUMIFS(Sessions!$I:$I,Sessions!$D:$D,$A7,Sessions!$B:$B,"ChatGPT") -> 0 | H7: =SUMIFS(Sessions!$I:$I,Sessions!$D:$D,$A7,Sessions!$B:$B,"Claude") -> 0 | I7: =SUMIFS(Sessions!$I:$I,Sessions!$D:$D,$A7,Sessions!$B:$B,"Gemini") -> 0 | J7: =SUMIFS(Sessions!$I:$I,Sessions!$D:$D,$A7,Sessions!$B:$B,"Copilot") -> 0 | K7: =IFERROR(F7/E7,"") -> 0 | L7: =IFERROR(J7/E7,"") -> 0 | M7: =IFERROR(E7/$E$106,"") -> 0.03216692 | N7: =IFERROR(F7/$F$106,"") -> 0 | O7: cited, no landings | P7: =IF(F7=0,"",_xlfn.MINIFS(Sessions!$A:$A,Sessions!$D:$D,$A7)) | Q7: =IF(F7=0,"",_xlfn.MAXIFS(Sessions!$A:$A,Sessions!$D:$D,$A7)) | R7: =SUMIFS(Sessions!$J:$J,Sessions!$D:$D,$A7) -> 0
A8: https://ipfirstresponse.ipaustralia.gov.au/options/check-your-idea-against-existing-patents | B8: /options/check-your-idea-against-existing-patents | C8: options | D8: Check your idea against existing patents | E8: 183 | F8: =SUMIFS(Sessions!$I:$I,Sessions!$D:$D,$A8) -> 21 | G8: =SUMIFS(Sessions!$I:$I,Sessions!$D:$D,$A8,Sessions!$B:$B,"ChatGPT") -> 20 | H8: =SUMIFS(Sessions!$I:$I,Sessions!$D:$D,$A8,Sessions!$B:$B,"Claude") -> 1 | I8: =SUMIFS(Sessions!$I:$I,Sessions!$D:$D,$A8,Sessions!$B:$B,"Gemini") -> 0 | J8: =SUMIFS(Sessions!$I:$I,Sessions!$D:$D,$A8,Sessions!$B:$B,"Copilot") -> 0 | K8: =IFERROR(F8/E8,"") -> 0.1147541 | L8: =IFERROR(J8/E8,"") -> 0 | M8: =IFERROR(E8/$E$106,"") -> 0.019886981 | N8: =IFERROR(F8/$F$106,"") -> 0.047404063 | O8: cited and landed | P8: =IF(F8=0,"",_xlfn.MINIFS(Sessions!$A:$A,Sessions!$D:$D,$A8)) -> 46210 | Q8: =IF(F8=0,"",_xlfn.MAXIFS(Sessions!$A:$A,Sessions!$D:$D,$A8)) -> 46273 | R8: =SUMIFS(Sessions!$J:$J,Sessions!$D:$D,$A8) -> 15
A9: https://ipfirstresponse.ipaustralia.gov.au/options/register-your-right-use-your-design-exclusively | B9: /options/register-your-right-use-your-design-exclusively | C9: options | D9: Register your right to use your design exclusively | E9: 177 | F9: =SUMIFS(Sessions!$I:$I,Sessions!$D:$D,$A9) -> 10 | G9: =SUMIFS(Sessions!$I:$I,Sessions!$D:$D,$A9,Sessions!$B:$B,"ChatGPT") -> 10 | H9: =SUMIFS(Sessions!$I:$I,Sessions!$D:$D,$A9,Sessions!$B:$B,"Claude") -> 0 | I9: =SUMIFS(Sessions!$I:$I,Sessions!$D:$D,$A9,Sessions!$B:$B,"Gemini") -> 0 | J9: =SUMIFS(Sessions!$I:$I,Sessions!$D:$D,$A9,Sessions!$B:$B,"Copilot") -> 0 | K9: =IFERROR(F9/E9,"") -> 0.056497175 | L9: =IFERROR(J9/E9,"") -> 0 | M9: =IFERROR(E9/$E$106,"") -> 0.019234949 | N9: =IFERROR(F9/$F$106,"") -> 0.022573363 | O9: cited and landed | P9: =IF(F9=0,"",_xlfn.MINIFS(Sessions!$A:$A,Sessions!$D:$D,$A9)) -> 46230 | Q9: =IF(F9=0,"",_xlfn.MAXIFS(Sessions!$A:$A,Sessions!$D:$D,$A9)) -> 46274 | R9: =SUMIFS(Sessions!$J:$J,Sessions!$D:$D,$A9) -> 9
A10: https://ipfirstresponse.ipaustralia.gov.au/ | B10: / | C10: (home) | D10: Homepage | E10: 138 | F10: =SUMIFS(Sessions!$I:$I,Sessions!$D:$D,$A10) -> 24 | G10: =SUMIFS(Sessions!$I:$I,Sessions!$D:$D,$A10,Sessions!$B:$B,"ChatGPT") -> 18 | H10: =SUMIFS(Sessions!$I:$I,Sessions!$D:$D,$A10,Sessions!$B:$B,"Claude") -> 1 | I10: =SUMIFS(Sessions!$I:$I,Sessions!$D:$D,$A10,Sessions!$B:$B,"Gemini") -> 5 | J10: =SUMIFS(Sessions!$I:$I,Sessions!$D:$D,$A10,Sessions!$B:$B,"Copilot") -> 0 | K10: =IFERROR(F10/E10,"") -> 0.17391304 | L10: =IFERROR(J10/E10,"") -> 0 | M10: =IFERROR(E10/$E$106,"") -> 0.01499674 | N10: =IFERROR(F10/$F$106,"") -> 0.054176072 | O10: cited and landed | P10: =IF(F10=0,"",_xlfn.MINIFS(Sessions!$A:$A,Sessions!$D:$D,$A10)) -> 46197 | Q10: =IF(F10=0,"",_xlfn.MAXIFS(Sessions!$A:$A,Sessions!$D:$D,$A10)) -> 46275 | R10: =SUMIFS(Sessions!$J:$J,Sessions!$D:$D,$A10) -> 18
A11: https://ipfirstresponse.ipaustralia.gov.au/infringement-101 | B11: /infringement-101 | C11: (top level) | D11: Infringement 101 | E11: 135 | F11: =SUMIFS(Sessions!$I:$I,Sessions!$D:$D,$A11) -> 2 | G11: =SUMIFS(Sessions!$I:$I,Sessions!$D:$D,$A11,Sessions!$B:$B,"ChatGPT") -> 1 | H11: =SUMIFS(Sessions!$I:$I,Sessions!$D:$D,$A11,Sessions!$B:$B,"Claude") -> 0 | I11: =SUMIFS(Sessions!$I:$I,Sessions!$D:$D,$A11,Sessions!$B:$B,"Gemini") -> 1 | J11: =SUMIFS(Sessions!$I:$I,Sessions!$D:$D,$A11,Sessions!$B:$B,"Copilot") -> 0 | K11: =IFERROR(F11/E11,"") -> 0.014814815 | L11: =IFERROR(J11/E11,"") -> 0 | M11: =IFERROR(E11/$E$106,"") -> 0.014670724 | N11: =IFERROR(F11/$F$106,"") -> 0.0045146727 | O11: cited and landed | P11: =IF(F11=0,"",_xlfn.MINIFS(Sessions!$A:$A,Sessions!$D:$D,$A11)) -> 46231 | Q11: =IF(F11=0,"",_xlfn.MAXIFS(Sessions!$A:$A,Sessions!$D:$D,$A11)) -> 46244 | R11: =SUMIFS(Sessions!$J:$J,Sessions!$D:$D,$A11) -> 2
A12: https://ipfirstresponse.ipaustralia.gov.au/options/trade-mark-non-use | B12: /options/trade-mark-non-use | C12: options | D12: Remove a trade mark from the register | E12: 123 | F12: =SUMIFS(Sessions!$I:$I,Sessions!$D:$D,$A12) -> 4 | G12: =SUMIFS(Sessions!$I:$I,Sessions!$D:$D,$A12,Sessions!$B:$B,"ChatGPT") -> 4 | H12: =SUMIFS(Sessions!$I:$I,Sessions!$D:$D,$A12,Sessions!$B:$B,"Claude") -> 0 | I12: =SUMIFS(Sessions!$I:$I,Sessions!$D:$D,$A12,Sessions!$B:$B,"Gemini") -> 0 | J12: =SUMIFS(Sessions!$I:$I,Sessions!$D:$D,$A12,Sessions!$B:$B,"Copilot") -> 0 | K12: =IFERROR(F12/E12,"") -> 0.032520325 | L12: =IFERROR(J12/E12,"") -> 0 | M12: =IFERROR(E12/$E$106,"") -> 0.013366659 | N12: =IFERROR(F12/$F$106,"") -> 0.0090293454 | O12: cited and landed | P12: =IF(F12=0,"",_xlfn.MINIFS(Sessions!$A:$A,Sessions!$D:$D,$A12)) -> 46209 | Q12: =IF(F12=0,"",_xlfn.MAXIFS(Sessions!$A:$A,Sessions!$D:$D,$A12)) -> 46272 | R12: =SUMIFS(Sessions!$J:$J,Sessions!$D:$D,$A12) -> 4
A13: https://ipfirstresponse.ipaustralia.gov.au/options/familiarise-yourself-ip-laws | B13: /options/familiarise-yourself-ip-laws | C13: options | D13: Familiarise yourself with IP laws | E13: 112 | F13: =SUMIFS(Sessions!$I:$I,Sessions!$D:$D,$A13) -> 7 | G13: =SUMIFS(Sessions!$I:$I,Sessions!$D:$D,$A13,Sessions!$B:$B,"ChatGPT") -> 7 | H13: =SUMIFS(Sessions!$I:$I,Sessions!$D:$D,$A13,Sessions!$B:$B,"Claude") -> 0 | I13: =SUMIFS(Sessions!$I:$I,Sessions!$D:$D,$A13,Sessions!$B:$B,"Gemini") -> 0 | J13: =SUMIFS(Sessions!$I:$I,Sessions!$D:$D,$A13,Sessions!$B:$B,"Copilot") -> 0 | K13: =IFERROR(F13/E13,"") -> 0.0625 | L13: =IFERROR(J13/E13,"") -> 0 | M13: =IFERROR(E13/$E$106,"") -> 0.012171267 | N13: =IFERROR(F13/$F$106,"") -> 0.015801354 | O13: cited and landed | P13: =IF(F13=0,"",_xlfn.MINIFS(Sessions!$A:$A,Sessions!$D:$D,$A13)) -> 46262 | Q13: =IF(F13=0,"",_xlfn.MAXIFS(Sessions!$A:$A,Sessions!$D:$D,$A13)) -> 46269 | R13: =SUMIFS(Sessions!$J:$J,Sessions!$D:$D,$A13) -> 5
A14: https://ipfirstresponse.ipaustralia.gov.au/options/infringement-101-patent-infringement | B14: /options/infringement-101-patent-infringement | C14: options | D14: Patent infringement | E14: 109 | F14: =SUMIFS(Sessions!$I:$I,Sessions!$D:$D,$A14) -> 3 | G14: =SUMIFS(Sessions!$I:$I,Sessions!$D:$D,$A14,Sessions!$B:$B,"ChatGPT") -> 3 | H14: =SUMIFS(Sessions!$I:$I,Sessions!$D:$D,$A14,Sessions!$B:$B,"Claude") -> 0 | I14: =SUMIFS(Sessions!$I:$I,Sessions!$D:$D,$A14,Sessions!$B:$B,"Gemini") -> 0 | J14: =SUMIFS(Sessions!$I:$I,Sessions!$D:$D,$A14,Sessions!$B:$B,"Copilot") -> 0 | K14: =IFERROR(F14/E14,"") -> 0.027522936 | L14: =IFERROR(J14/E14,"") -> 0 | M14: =IFERROR(E14/$E$106,"") -> 0.011845251 | N14: =IFERROR(F14/$F$106,"") -> 0.006772009 | O14: cited and landed | P14: =IF(F14=0,"",_xlfn.MINIFS(Sessions!$A:$A,Sessions!$D:$D,$A14)) -> 46230 | Q14: =IF(F14=0,"",_xlfn.MAXIFS(Sessions!$A:$A,Sessions!$D:$D,$A14)) -> 46258 | R14: =SUMIFS(Sessions!$J:$J,Sessions!$D:$D,$A14) -> 3
A15: https://ipfirstresponse.ipaustralia.gov.au/options/infringement-101-unregistered-trade-marks | B15: /options/infringement-101-unregistered-trade-marks | C15: options | D15: Unregistered trade marks | E15: 100 | F15: =SUMIFS(Sessions!$I:$I,Sessions!$D:$D,$A15) -> 27 | G15: =SUMIFS(Sessions!$I:$I,Sessions!$D:$D,$A15,Sessions!$B:$B,"ChatGPT") -> 25 | H15: =SUMIFS(Sessions!$I:$I,Sessions!$D:$D,$A15,Sessions!$B:$B,"Claude") -> 2 | I15: =SUMIFS(Sessions!$I:$I,Sessions!$D:$D,$A15,Sessions!$B:$B,"Gemini") -> 0 | J15: =SUMIFS(Sessions!$I:$I,Sessions!$D:$D,$A15,Sessions!$B:$B,"Copilot") -> 0 | K15: =IFERROR(F15/E15,"") -> 0.27 | L15: =IFERROR(J15/E15,"") -> 0 | M15: =IFERROR(E15/$E$106,"") -> 0.010867203 | N15: =IFERROR(F15/$F$106,"") -> 0.060948081 | O15: cited and landed | P15: =IF(F15=0,"",_xlfn.MINIFS(Sessions!$A:$A,Sessions!$D:$D,$A15)) -> 46157 | Q15: =IF(F15=0,"",_xlfn.MAXIFS(Sessions!$A:$A,Sessions!$D:$D,$A15)) -> 46273 | R15: =SUMIFS(Sessions!$J:$J,Sessions!$D:$D,$A15) -> 22
A16: https://ipfirstresponse.ipaustralia.gov.au/options/what-does-ip-protection-mean-my-business | B16: /options/what-does-ip-protection-mean-my-business | C16: options | E16: 99 | F16: =SUMIFS(Sessions!$I:$I,Sessions!$D:$D,$A16) -> 0 | G16: =SUMIFS(Sessions!$I:$I,Sessions!$D:$D,$A16,Sessions!$B:$B,"ChatGPT") -> 0 | H16: =SUMIFS(Sessions!$I:$I,Sessions!$D:$D,$A16,Sessions!$B:$B,"Claude") -> 0 | I16: =SUMIFS(Sessions!$I:$I,Sessions!$D:$D,$A16,Sessions!$B:$B,"Gemini") -> 0 | J16: =SUMIFS(Sessions!$I:$I,Sessions!$D:$D,$A16,Sessions!$B:$B,"Copilot") -> 0 | K16: =IFERROR(F16/E16,"") -> 0 | L16: =IFERROR(J16/E16,"") -> 0 | M16: =IFERROR(E16/$E$106,"") -> 0.010758531 | N16: =IFERROR(F16/$F$106,"") -> 0 | O16: cited, no landings | P16: =IF(F16=0,"",_xlfn.MINIFS(Sessions!$A:$A,Sessions!$D:$D,$A16)) | Q16: =IF(F16=0,"",_xlfn.MAXIFS(Sessions!$A:$A,Sessions!$D:$D,$A16)) | R16: =SUMIFS(Sessions!$J:$J,Sessions!$D:$D,$A16) -> 0
A17: https://ipfirstresponse.ipaustralia.gov.au/blogs/ive-got-abn-and-registered-business-name-do-i-need-registered-trade-mark-too | B17: /blogs/ive-got-abn-and-registered-business-name-do-i-need-registered-trade-mark-too | C17: blogs | D17: I’ve got an ABN and a registered business name – do I need a registered trade mark too? | E17: 90 | F17: =SUMIFS(Sessions!$I:$I,Sessions!$D:$D,$A17) -> 5 | G17: =SUMIFS(Sessions!$I:$I,Sessions!$D:$D,$A17,Sessions!$B:$B,"ChatGPT") -> 5 | H17: =SUMIFS(Sessions!$I:$I,Sessions!$D:$D,$A17,Sessions!$B:$B,"Claude") -> 0 | I17: =SUMIFS(Sessions!$I:$I,Sessions!$D:$D,$A17,Sessions!$B:$B,"Gemini") -> 0 | J17: =SUMIFS(Sessions!$I:$I,Sessions!$D:$D,$A17,Sessions!$B:$B,"Copilot") -> 0 | K17: =IFERROR(F17/E17,"") -> 0.055555556 | L17: =IFERROR(J17/E17,"") -> 0 | M17: =IFERROR(E17/$E$106,"") -> 0.0097804825 | N17: =IFERROR(F17/$F$106,"") -> 0.011286682 | O17: cited and landed | P17: =IF(F17=0,"",_xlfn.MINIFS(Sessions!$A:$A,Sessions!$D:$D,$A17)) -> 46197 | Q17: =IF(F17=0,"",_xlfn.MAXIFS(Sessions!$A:$A,Sessions!$D:$D,$A17)) -> 46273 | R17: =SUMIFS(Sessions!$J:$J,Sessions!$D:$D,$A17) -> 5
A18: https://ipfirstresponse.ipaustralia.gov.au/options/how-can-i-make-complaint-about-lawyer-or-attorney | B18: /options/how-can-i-make-complaint-about-lawyer-or-attorney | C18: options | E18: 89 | F18: =SUMIFS(Sessions!$I:$I,Sessions!$D:$D,$A18) -> 0 | G18: =SUMIFS(Sessions!$I:$I,Sessions!$D:$D,$A18,Sessions!$B:$B,"ChatGPT") -> 0 | H18: =SUMIFS(Sessions!$I:$I,Sessions!$D:$D,$A18,Sessions!$B:$B,"Claude") -> 0 | I18: =SUMIFS(Sessions!$I:$I,Sessions!$D:$D,$A18,Sessions!$B:$B,"Gemini") -> 0 | J18: =SUMIFS(Sessions!$I:$I,Sessions!$D:$D,$A18,Sessions!$B:$B,"Copilot") -> 0 | K18: =IFERROR(F18/E18,"") -> 0 | L18: =IFERROR(J18/E18,"") -> 0 | M18: =IFERROR(E18/$E$106,"") -> 0.0096718105 | N18: =IFERROR(F18/$F$106,"") -> 0 | O18: cited, no landings | P18: =IF(F18=0,"",_xlfn.MINIFS(Sessions!$A:$A,Sessions!$D:$D,$A18)) | Q18: =IF(F18=0,"",_xlfn.MAXIFS(Sessions!$A:$A,Sessions!$D:$D,$A18)) | R18: =SUMIFS(Sessions!$J:$J,Sessions!$D:$D,$A18) -> 0
A19: https://ipfirstresponse.ipaustralia.gov.au/options/request-ip-australia-remove-unused-trade-mark-defend-your-right | B19: /options/request-ip-australia-remove-unused-trade-mark-defend-your-right | C19: options | E19: 89 | F19: =SUMIFS(Sessions!$I:$I,Sessions!$D:$D,$A19) -> 0 | G19: =SUMIFS(Sessions!$I:$I,Sessions!$D:$D,$A19,Sessions!$B:$B,"ChatGPT") -> 0 | H19: =SUMIFS(Sessions!$I:$I,Sessions!$D:$D,$A19,Sessions!$B:$B,"Claude") -> 0 | I19: =SUMIFS(Sessions!$I:$I,Sessions!$D:$D,$A19,Sessions!$B:$B,"Gemini") -> 0 | J19: =SUMIFS(Sessions!$I:$I,Sessions!$D:$D,$A19,Sessions!$B:$B,"Copilot") -> 0 | K19: =IFERROR(F19/E19,"") -> 0 | L19: =IFERROR(J19/E19,"") -> 0 | M19: =IFERROR(E19/$E$106,"") -> 0.0096718105 | N19: =IFERROR(F19/$F$106,"") -> 0 | O19: cited, no landings | P19: =IF(F19=0,"",_xlfn.MINIFS(Sessions!$A:$A,Sessions!$D:$D,$A19)) | Q19: =IF(F19=0,"",_xlfn.MAXIFS(Sessions!$A:$A,Sessions!$D:$D,$A19)) | R19: =SUMIFS(Sessions!$J:$J,Sessions!$D:$D,$A19) -> 0
A20: https://ipfirstresponse.ipaustralia.gov.au/options/develop-strategy-manage-your-ip | B20: /options/develop-strategy-manage-your-ip | C20: options | D20: Develop a strategy to manage your IP | E20: 85 | F20: =SUMIFS(Sessions!$I:$I,Sessions!$D:$D,$A20) -> 5 | G20: =SUMIFS(Sessions!$I:$I,Sessions!$D:$D,$A20,Sessions!$B:$B,"ChatGPT") -> 5 | H20: =SUMIFS(Sessions!$I:$I,Sessions!$D:$D,$A20,Sessions!$B:$B,"Claude") -> 0 | I20: =SUMIFS(Sessions!$I:$I,Sessions!$D:$D,$A20,Sessions!$B:$B,"Gemini") -> 0 | J20: =SUMIFS(Sessions!$I:$I,Sessions!$D:$D,$A20,Sessions!$B:$B,"Copilot") -> 0 | K20: =IFERROR(F20/E20,"") -> 0.058823529 | L20: =IFERROR(J20/E20,"") -> 0 | M20: =IFERROR(E20/$E$106,"") -> 0.0092371224 | N20: =IFERROR(F20/$F$106,"") -> 0.011286682 | O20: cited and landed | P20: =IF(F20=0,"",_xlfn.MINIFS(Sessions!$A:$A,Sessions!$D:$D,$A20)) -> 46260 | Q20: =IF(F20=0,"",_xlfn.MAXIFS(Sessions!$A:$A,Sessions!$D:$D,$A20)) -> 46267 | R20: =SUMIFS(Sessions!$J:$J,Sessions!$D:$D,$A20) -> 3
A21: https://ipfirstresponse.ipaustralia.gov.au/options/ASBFEO | B21: /options/ASBFEO | C21: options | E21: 80 | F21: =SUMIFS(Sessions!$I:$I,Sessions!$D:$D,$A21) -> 0 | G21: =SUMIFS(Sessions!$I:$I,Sessions!$D:$D,$A21,Sessions!$B:$B,"ChatGPT") -> 0 | H21: =SUMIFS(Sessions!$I:$I,Sessions!$D:$D,$A21,Sessions!$B:$B,"Claude") -> 0 | I21: =SUMIFS(Sessions!$I:$I,Sessions!$D:$D,$A21,Sessions!$B:$B,"Gemini") -> 0 | J21: =SUMIFS(Sessions!$I:$I,Sessions!$D:$D,$A21,Sessions!$B:$B,"Copilot") -> 0 | K21: =IFERROR(F21/E21,"") -> 0 | L21: =IFERROR(J21/E21,"") -> 0 | M21: =IFERROR(E21/$E$106,"") -> 0.0086937622 | N21: =IFERROR(F21/$F$106,"") -> 0 | O21: cited, no landings | P21: =IF(F21=0,"",_xlfn.MINIFS(Sessions!$A:$A,Sessions!$D:$D,$A21)) | Q21: =IF(F21=0,"",_xlfn.MAXIFS(Sessions!$A:$A,Sessions!$D:$D,$A21)) | R21: =SUMIFS(Sessions!$J:$J,Sessions!$D:$D,$A21) -> 0
A22: https://ipfirstresponse.ipaustralia.gov.au/options/court-patents | B22: /options/court-patents | C22: options | D22: Seek binding, authoritative decisions | E22: 77 | F22: =SUMIFS(Sessions!$I:$I,Sessions!$D:$D,$A22) -> 1 | G22: =SUMIFS(Sessions!$I:$I,Sessions!$D:$D,$A22,Sessions!$B:$B,"ChatGPT") -> 0 | H22: =SUMIFS(Sessions!$I:$I,Sessions!$D:$D,$A22,Sessions!$B:$B,"Claude") -> 1 | I22: =SUMIFS(Sessions!$I:$I,Sessions!$D:$D,$A22,Sessions!$B:$B,"Gemini") -> 0 | J22: =SUMIFS(Sessions!$I:$I,Sessions!$D:$D,$A22,Sessions!$B:$B,"Copilot") -> 0 | K22: =IFERROR(F22/E22,"") -> 0.012987013 | L22: =IFERROR(J22/E22,"") -> 0 | M22: =IFERROR(E22/$E$106,"") -> 0.0083677461 | N22: =IFERROR(F22/$F$106,"") -> 0.0022573363 | O22: cited and landed | P22: =IF(F22=0,"",_xlfn.MINIFS(Sessions!$A:$A,Sessions!$D:$D,$A22)) -> 46167 | Q22: =IF(F22=0,"",_xlfn.MAXIFS(Sessions!$A:$A,Sessions!$D:$D,$A22)) -> 46167 | R22: =SUMIFS(Sessions!$J:$J,Sessions!$D:$D,$A22) -> 1
A23: https://ipfirstresponse.ipaustralia.gov.au/options/infringement-101-design-infringement | B23: /options/infringement-101-design-infringement | C23: options | D23: Design infringement | E23: 75 | F23: =SUMIFS(Sessions!$I:$I,Sessions!$D:$D,$A23) -> 11 | G23: =SUMIFS(Sessions!$I:$I,Sessions!$D:$D,$A23,Sessions!$B:$B,"ChatGPT") -> 11 | H23: =SUMIFS(Sessions!$I:$I,Sessions!$D:$D,$A23,Sessions!$B:$B,"Claude") -> 0 | I23: =SUMIFS(Sessions!$I:$I,Sessions!$D:$D,$A23,Sessions!$B:$B,"Gemini") -> 0 | J23: =SUMIFS(Sessions!$I:$I,Sessions!$D:$D,$A23,Sessions!$B:$B,"Copilot") -> 0 | K23: =IFERROR(F23/E23,"") -> 0.14666667 | L23: =IFERROR(J23/E23,"") -> 0 | M23: =IFERROR(E23/$E$106,"") -> 0.0081504021 | N23: =IFERROR(F23/$F$106,"") -> 0.0248307 | O23: cited and landed | P23: =IF(F23=0,"",_xlfn.MINIFS(Sessions!$A:$A,Sessions!$D:$D,$A23)) -> 46161 | Q23: =IF(F23=0,"",_xlfn.MAXIFS(Sessions!$A:$A,Sessions!$D:$D,$A23)) -> 46270 | R23: =SUMIFS(Sessions!$J:$J,Sessions!$D:$D,$A23) -> 10
A24: https://ipfirstresponse.ipaustralia.gov.au/options/infringement-101-how-avoid-infringing-others-intellectual-property | B24: /options/infringement-101-how-avoid-infringing-others-intellectual-property | C24: options | D24: How to avoid infringing others' intellectual property | E24: 75 | F24: =SUMIFS(Sessions!$I:$I,Sessions!$D:$D,$A24) -> 4 | G24: =SUMIFS(Sessions!$I:$I,Sessions!$D:$D,$A24,Sessions!$B:$B,"ChatGPT") -> 3 | H24: =SUMIFS(Sessions!$I:$I,Sessions!$D:$D,$A24,Sessions!$B:$B,"Claude") -> 0 | I24: =SUMIFS(Sessions!$I:$I,Sessions!$D:$D,$A24,Sessions!$B:$B,"Gemini") -> 0 | J24: =SUMIFS(Sessions!$I:$I,Sessions!$D:$D,$A24,Sessions!$B:$B,"Copilot") -> 1 | K24: =IFERROR(F24/E24,"") -> 0.053333333 | L24: =IFERROR(J24/E24,"") -> 0.013333333 | M24: =IFERROR(E24/$E$106,"") -> 0.0081504021 | N24: =IFERROR(F24/$F$106,"") -> 0.0090293454 | O24: cited and landed | P24: =IF(F24=0,"",_xlfn.MINIFS(Sessions!$A:$A,Sessions!$D:$D,$A24)) -> 46248 | Q24: =IF(F24=0,"",_xlfn.MAXIFS(Sessions!$A:$A,Sessions!$D:$D,$A24)) -> 46275 | R24: =SUMIFS(Sessions!$J:$J,Sessions!$D:$D,$A24) -> 4
A25: https://ipfirstresponse.ipaustralia.gov.au/options/report-scam-fraud-or-risk-public-interest | B25: /options/report-scam-fraud-or-risk-public-interest | C25: options | D25: Report a scam, fraud or risk to public interest | E25: 71 | F25: =SUMIFS(Sessions!$I:$I,Sessions!$D:$D,$A25) -> 6 | G25: =SUMIFS(Sessions!$I:$I,Sessions!$D:$D,$A25,Sessions!$B:$B,"ChatGPT") -> 1 | H25: =SUMIFS(Sessions!$I:$I,Sessions!$D:$D,$A25,Sessions!$B:$B,"Claude") -> 1 | I25: =SUMIFS(Sessions!$I:$I,Sessions!$D:$D,$A25,Sessions!$B:$B,"Gemini") -> 4 | J25: =SUMIFS(Sessions!$I:$I,Sessions!$D:$D,$A25,Sessions!$B:$B,"Copilot") -> 0 | K25: =IFERROR(F25/E25,"") -> 0.084507042 | L25: =IFERROR(J25/E25,"") -> 0 | M25: =IFERROR(E25/$E$106,"") -> 0.007715714 | N25: =IFERROR(F25/$F$106,"") -> 0.013544018 | O25: cited and landed | P25: =IF(F25=0,"",_xlfn.MINIFS(Sessions!$A:$A,Sessions!$D:$D,$A25)) -> 46183 | Q25: =IF(F25=0,"",_xlfn.MAXIFS(Sessions!$A:$A,Sessions!$D:$D,$A25)) -> 46251 | R25: =SUMIFS(Sessions!$J:$J,Sessions!$D:$D,$A25) -> 6
A26: https://ipfirstresponse.ipaustralia.gov.au/options/infringement-101-what-do-if-someone-infringes-your-ip | B26: /options/infringement-101-what-do-if-someone-infringes-your-ip | C26: options | D26: What to do if someone infringes your IP | E26: 71 | F26: =SUMIFS(Sessions!$I:$I,Sessions!$D:$D,$A26) -> 1 | G26: =SUMIFS(Sessions!$I:$I,Sessions!$D:$D,$A26,Sessions!$B:$B,"ChatGPT") -> 1 | H26: =SUMIFS(Sessions!$I:$I,Sessions!$D:$D,$A26,Sessions!$B:$B,"Claude") -> 0 | I26: =SUMIFS(Sessions!$I:$I,Sessions!$D:$D,$A26,Sessions!$B:$B,"Gemini") -> 0 | J26: =SUMIFS(Sessions!$I:$I,Sessions!$D:$D,$A26,Sessions!$B:$B,"Copilot") -> 0 | K26: =IFERROR(F26/E26,"") -> 0.014084507 | L26: =IFERROR(J26/E26,"") -> 0 | M26: =IFERROR(E26/$E$106,"") -> 0.007715714 | N26: =IFERROR(F26/$F$106,"") -> 0.0022573363 | O26: cited and landed | P26: =IF(F26=0,"",_xlfn.MINIFS(Sessions!$A:$A,Sessions!$D:$D,$A26)) -> 46244 | Q26: =IF(F26=0,"",_xlfn.MAXIFS(Sessions!$A:$A,Sessions!$D:$D,$A26)) -> 46244 | R26: =SUMIFS(Sessions!$J:$J,Sessions!$D:$D,$A26) -> 1
A27: https://ipfirstresponse.ipaustralia.gov.au/options/dispute-au-domain-name | B27: /options/dispute-au-domain-name | C27: options | D27: Dispute a domain name that infringes your trade mark | E27: 67 | F27: =SUMIFS(Sessions!$I:$I,Sessions!$D:$D,$A27) -> 3 | G27: =SUMIFS(Sessions!$I:$I,Sessions!$D:$D,$A27,Sessions!$B:$B,"ChatGPT") -> 3 | H27: =SUMIFS(Sessions!$I:$I,Sessions!$D:$D,$A27,Sessions!$B:$B,"Claude") -> 0 | I27: =SUMIFS(Sessions!$I:$I,Sessions!$D:$D,$A27,Sessions!$B:$B,"Gemini") -> 0 | J27: =SUMIFS(Sessions!$I:$I,Sessions!$D:$D,$A27,Sessions!$B:$B,"Copilot") -> 0 | K27: =IFERROR(F27/E27,"") -> 0.044776119 | L27: =IFERROR(J27/E27,"") -> 0 | M27: =IFERROR(E27/$E$106,"") -> 0.0072810259 | N27: =IFERROR(F27/$F$106,"") -> 0.006772009 | O27: cited and landed | P27: =IF(F27=0,"",_xlfn.MINIFS(Sessions!$A:$A,Sessions!$D:$D,$A27)) -> 46251 | Q27: =IF(F27=0,"",_xlfn.MAXIFS(Sessions!$A:$A,Sessions!$D:$D,$A27)) -> 46264 | R27: =SUMIFS(Sessions!$J:$J,Sessions!$D:$D,$A27) -> 3
A28: https://ipfirstresponse.ipaustralia.gov.au/options/considerations-when-using-artificial-intelligence-create-ip-0 | B28: /options/considerations-when-using-artificial-intelligence-create-ip-0 | C28: options | D28: Considerations when using artificial intelligence to create IP | E28: 60 | F28: =SUMIFS(Sessions!$I:$I,Sessions!$D:$D,$A28) -> 44 | G28: =SUMIFS(Sessions!$I:$I,Sessions!$D:$D,$A28,Sessions!$B:$B,"ChatGPT") -> 42 | H28: =SUMIFS(Sessions!$I:$I,Sessions!$D:$D,$A28,Sessions!$B:$B,"Claude") -> 2 | I28: =SUMIFS(Sessions!$I:$I,Sessions!$D:$D,$A28,Sessions!$B:$B,"Gemini") -> 0 | J28: =SUMIFS(Sessions!$I:$I,Sessions!$D:$D,$A28,Sessions!$B:$B,"Copilot") -> 0 | K28: =IFERROR(F28/E28,"") -> 0.73333333 | L28: =IFERROR(J28/E28,"") -> 0 | M28: =IFERROR(E28/$E$106,"") -> 0.0065203217 | N28: =IFERROR(F28/$F$106,"") -> 0.099322799 | O28: cited and landed | P28: =IF(F28=0,"",_xlfn.MINIFS(Sessions!$A:$A,Sessions!$D:$D,$A28)) -> 46158 | Q28: =IF(F28=0,"",_xlfn.MAXIFS(Sessions!$A:$A,Sessions!$D:$D,$A28)) -> 46275 | R28: =SUMIFS(Sessions!$J:$J,Sessions!$D:$D,$A28) -> 27
A29: https://ipfirstresponse.ipaustralia.gov.au/blogs/why-every-creative-business-needs-ip-strategy-day-one | B29: /blogs/why-every-creative-business-needs-ip-strategy-day-one | C29: blogs | E29: 60 | F29: =SUMIFS(Sessions!$I:$I,Sessions!$D:$D,$A29) -> 0 | G29: =SUMIFS(Sessions!$I:$I,Sessions!$D:$D,$A29,Sessions!$B:$B,"ChatGPT") -> 0 | H29: =SUMIFS(Sessions!$I:$I,Sessions!$D:$D,$A29,Sessions!$B:$B,"Claude") -> 0 | I29: =SUMIFS(Sessions!$I:$I,Sessions!$D:$D,$A29,Sessions!$B:$B,"Gemini") -> 0 | J29: =SUMIFS(Sessions!$I:$I,Sessions!$D:$D,$A29,Sessions!$B:$B,"Copilot") -> 0 | K29: =IFERROR(F29/E29,"") -> 0 | L29: =IFERROR(J29/E29,"") -> 0 | M29: =IFERROR(E29/$E$106,"") -> 0.0065203217 | N29: =IFERROR(F29/$F$106,"") -> 0 | O29: cited, no landings | P29: =IF(F29=0,"",_xlfn.MINIFS(Sessions!$A:$A,Sessions!$D:$D,$A29)) | Q29: =IF(F29=0,"",_xlfn.MAXIFS(Sessions!$A:$A,Sessions!$D:$D,$A29)) | R29: =SUMIFS(Sessions!$J:$J,Sessions!$D:$D,$A29) -> 0
A30: https://ipfirstresponse.ipaustralia.gov.au/options/what-happens-ip-australia-hearing | B30: /options/what-happens-ip-australia-hearing | C30: options | E30: 54 | F30: =SUMIFS(Sessions!$I:$I,Sessions!$D:$D,$A30) -> 0 | G30: =SUMIFS(Sessions!$I:$I,Sessions!$D:$D,$A30,Sessions!$B:$B,"ChatGPT") -> 0 | H30: =SUMIFS(Sessions!$I:$I,Sessions!$D:$D,$A30,Sessions!$B:$B,"Claude") -> 0 | I30: =SUMIFS(Sessions!$I:$I,Sessions!$D:$D,$A30,Sessions!$B:$B,"Gemini") -> 0 | J30: =SUMIFS(Sessions!$I:$I,Sessions!$D:$D,$A30,Sessions!$B:$B,"Copilot") -> 0 | K30: =IFERROR(F30/E30,"") -> 0 | L30: =IFERROR(J30/E30,"") -> 0 | M30: =IFERROR(E30/$E$106,"") -> 0.0058682895 | N30: =IFERROR(F30/$F$106,"") -> 0 | O30: cited, no landings | P30: =IF(F30=0,"",_xlfn.MINIFS(Sessions!$A:$A,Sessions!$D:$D,$A30)) | Q30: =IF(F30=0,"",_xlfn.MAXIFS(Sessions!$A:$A,Sessions!$D:$D,$A30)) | R30: =SUMIFS(Sessions!$J:$J,Sessions!$D:$D,$A30) -> 0
A31: https://ipfirstresponse.ipaustralia.gov.au/options/free-ip-tools-you-can-use | B31: /options/free-ip-tools-you-can-use | C31: options | D31: Free IP tools you can use | E31: 53 | F31: =SUMIFS(Sessions!$I:$I,Sessions!$D:$D,$A31) -> 1 | G31: =SUMIFS(Sessions!$I:$I,Sessions!$D:$D,$A31,Sessions!$B:$B,"ChatGPT") -> 1 | H31: =SUMIFS(Sessions!$I:$I,Sessions!$D:$D,$A31,Sessions!$B:$B,"Claude") -> 0 | I31: =SUMIFS(Sessions!$I:$I,Sessions!$D:$D,$A31,Sessions!$B:$B,"Gemini") -> 0 | J31: =SUMIFS(Sessions!$I:$I,Sessions!$D:$D,$A31,Sessions!$B:$B,"Copilot") -> 0 | K31: =IFERROR(F31/E31,"") -> 0.018867925 | L31: =IFERROR(J31/E31,"") -> 0 | M31: =IFERROR(E31/$E$106,"") -> 0.0057596175 | N31: =IFERROR(F31/$F$106,"") -> 0.0022573363 | O31: cited and landed | P31: =IF(F31=0,"",_xlfn.MINIFS(Sessions!$A:$A,Sessions!$D:$D,$A31)) -> 46266 | Q31: =IF(F31=0,"",_xlfn.MAXIFS(Sessions!$A:$A,Sessions!$D:$D,$A31)) -> 46266 | R31: =SUMIFS(Sessions!$J:$J,Sessions!$D:$D,$A31) -> 1
A32: https://ipfirstresponse.ipaustralia.gov.au/options/check-your-product-against-existing-designs | B32: /options/check-your-product-against-existing-designs | C32: options | D32: Check your product against existing designs | E32: 51 | F32: =SUMIFS(Sessions!$I:$I,Sessions!$D:$D,$A32) -> 11 | G32: =SUMIFS(Sessions!$I:$I,Sessions!$D:$D,$A32,Sessions!$B:$B,"ChatGPT") -> 11 | H32: =SUMIFS(Sessions!$I:$I,Sessions!$D:$D,$A32,Sessions!$B:$B,"Claude") -> 0 | I32: =SUMIFS(Sessions!$I:$I,Sessions!$D:$D,$A32,Sessions!$B:$B,"Gemini") -> 0 | J32: =SUMIFS(Sessions!$I:$I,Sessions!$D:$D,$A32,Sessions!$B:$B,"Copilot") -> 0 | K32: =IFERROR(F32/E32,"") -> 0.21568627 | L32: =IFERROR(J32/E32,"") -> 0 | M32: =IFERROR(E32/$E$106,"") -> 0.0055422734 | N32: =IFERROR(F32/$F$106,"") -> 0.0248307 | O32: cited and landed | P32: =IF(F32=0,"",_xlfn.MINIFS(Sessions!$A:$A,Sessions!$D:$D,$A32)) -> 46245 | Q32: =IF(F32=0,"",_xlfn.MAXIFS(Sessions!$A:$A,Sessions!$D:$D,$A32)) -> 46265 | R32: =SUMIFS(Sessions!$J:$J,Sessions!$D:$D,$A32) -> 8
A33: https://ipfirstresponse.ipaustralia.gov.au/options/mediation | B33: /options/mediation | C33: options | D33: Resolve IP issues with the help of a third party | E33: 49 | F33: =SUMIFS(Sessions!$I:$I,Sessions!$D:$D,$A33) -> 2 | G33: =SUMIFS(Sessions!$I:$I,Sessions!$D:$D,$A33,Sessions!$B:$B,"ChatGPT") -> 2 | H33: =SUMIFS(Sessions!$I:$I,Sessions!$D:$D,$A33,Sessions!$B:$B,"Claude") -> 0 | I33: =SUMIFS(Sessions!$I:$I,Sessions!$D:$D,$A33,Sessions!$B:$B,"Gemini") -> 0 | J33: =SUMIFS(Sessions!$I:$I,Sessions!$D:$D,$A33,Sessions!$B:$B,"Copilot") -> 0 | K33: =IFERROR(F33/E33,"") -> 0.040816327 | L33: =IFERROR(J33/E33,"") -> 0 | M33: =IFERROR(E33/$E$106,"") -> 0.0053249294 | N33: =IFERROR(F33/$F$106,"") -> 0.0045146727 | O33: cited and landed | P33: =IF(F33=0,"",_xlfn.MINIFS(Sessions!$A:$A,Sessions!$D:$D,$A33)) -> 46229 | Q33: =IF(F33=0,"",_xlfn.MAXIFS(Sessions!$A:$A,Sessions!$D:$D,$A33)) -> 46229 | R33: =SUMIFS(Sessions!$J:$J,Sessions!$D:$D,$A33) -> 1
A34: https://ipfirstresponse.ipaustralia.gov.au/options/challenge-registration-new-trade-mark | B34: /options/challenge-registration-new-trade-mark | C34: options | D34: Challenge the registration of a new trade mark | E34: 48 | F34: =SUMIFS(Sessions!$I:$I,Sessions!$D:$D,$A34) -> 5 | G34: =SUMIFS(Sessions!$I:$I,Sessions!$D:$D,$A34,Sessions!$B:$B,"ChatGPT") -> 4 | H34: =SUMIFS(Sessions!$I:$I,Sessions!$D:$D,$A34,Sessions!$B:$B,"Claude") -> 1 | I34: =SUMIFS(Sessions!$I:$I,Sessions!$D:$D,$A34,Sessions!$B:$B,"Gemini") -> 0 | J34: =SUMIFS(Sessions!$I:$I,Sessions!$D:$D,$A34,Sessions!$B:$B,"Copilot") -> 0 | K34: =IFERROR(F34/E34,"") -> 0.10416667 | L34: =IFERROR(J34/E34,"") -> 0 | M34: =IFERROR(E34/$E$106,"") -> 0.0052162573 | N34: =IFERROR(F34/$F$106,"") -> 0.011286682 | O34: cited and landed | P34: =IF(F34=0,"",_xlfn.MINIFS(Sessions!$A:$A,Sessions!$D:$D,$A34)) -> 46256 | Q34: =IF(F34=0,"",_xlfn.MAXIFS(Sessions!$A:$A,Sessions!$D:$D,$A34)) -> 46273 | R34: =SUMIFS(Sessions!$J:$J,Sessions!$D:$D,$A34) -> 3
A35: https://ipfirstresponse.ipaustralia.gov.au/options/stop-infringing-goods-entering-country | B35: /options/stop-infringing-goods-entering-country | C35: options | D35: Stop infringing goods entering the country | E35: 43 | F35: =SUMIFS(Sessions!$I:$I,Sessions!$D:$D,$A35) -> 3 | G35: =SUMIFS(Sessions!$I:$I,Sessions!$D:$D,$A35,Sessions!$B:$B,"ChatGPT") -> 3 | H35: =SUMIFS(Sessions!$I:$I,Sessions!$D:$D,$A35,Sessions!$B:$B,"Claude") -> 0 | I35: =SUMIFS(Sessions!$I:$I,Sessions!$D:$D,$A35,Sessions!$B:$B,"Gemini") -> 0 | J35: =SUMIFS(Sessions!$I:$I,Sessions!$D:$D,$A35,Sessions!$B:$B,"Copilot") -> 0 | K35: =IFERROR(F35/E35,"") -> 0.069767442 | L35: =IFERROR(J35/E35,"") -> 0 | M35: =IFERROR(E35/$E$106,"") -> 0.0046728972 | N35: =IFERROR(F35/$F$106,"") -> 0.006772009 | O35: cited and landed | P35: =IF(F35=0,"",_xlfn.MINIFS(Sessions!$A:$A,Sessions!$D:$D,$A35)) -> 46163 | Q35: =IF(F35=0,"",_xlfn.MAXIFS(Sessions!$A:$A,Sessions!$D:$D,$A35)) -> 46206 | R35: =SUMIFS(Sessions!$J:$J,Sessions!$D:$D,$A35) -> 3
A36: https://ipfirstresponse.ipaustralia.gov.au/options/request-early-examination-your-application-ip-rights | B36: /options/request-early-examination-your-application-ip-rights | C36: options | E36: 42 | F36: =SUMIFS(Sessions!$I:$I,Sessions!$D:$D,$A36) -> 0 | G36: =SUMIFS(Sessions!$I:$I,Sessions!$D:$D,$A36,Sessions!$B:$B,"ChatGPT") -> 0 | H36: =SUMIFS(Sessions!$I:$I,Sessions!$D:$D,$A36,Sessions!$B:$B,"Claude") -> 0 | I36: =SUMIFS(Sessions!$I:$I,Sessions!$D:$D,$A36,Sessions!$B:$B,"Gemini") -> 0 | J36: =SUMIFS(Sessions!$I:$I,Sessions!$D:$D,$A36,Sessions!$B:$B,"Copilot") -> 0 | K36: =IFERROR(F36/E36,"") -> 0 | L36: =IFERROR(J36/E36,"") -> 0 | M36: =IFERROR(E36/$E$106,"") -> 0.0045642252 | N36: =IFERROR(F36/$F$106,"") -> 0 | O36: cited, no landings | P36: =IF(F36=0,"",_xlfn.MINIFS(Sessions!$A:$A,Sessions!$D:$D,$A36)) | Q36: =IF(F36=0,"",_xlfn.MAXIFS(Sessions!$A:$A,Sessions!$D:$D,$A36)) | R36: =SUMIFS(Sessions!$J:$J,Sessions!$D:$D,$A36) -> 0
A37: https://ipfirstresponse.ipaustralia.gov.au/options/apply-patent-protect-your-invention-being-copied | B37: /options/apply-patent-protect-your-invention-being-copied | C37: options | D37: Apply for a patent to protect your invention from being copied | E37: 41 | F37: =SUMIFS(Sessions!$I:$I,Sessions!$D:$D,$A37) -> 2 | G37: =SUMIFS(Sessions!$I:$I,Sessions!$D:$D,$A37,Sessions!$B:$B,"ChatGPT") -> 2 | H37: =SUMIFS(Sessions!$I:$I,Sessions!$D:$D,$A37,Sessions!$B:$B,"Claude") -> 0 | I37: =SUMIFS(Sessions!$I:$I,Sessions!$D:$D,$A37,Sessions!$B:$B,"Gemini") -> 0 | J37: =SUMIFS(Sessions!$I:$I,Sessions!$D:$D,$A37,Sessions!$B:$B,"Copilot") -> 0 | K37: =IFERROR(F37/E37,"") -> 0.048780488 | L37: =IFERROR(J37/E37,"") -> 0 | M37: =IFERROR(E37/$E$106,"") -> 0.0044555531 | N37: =IFERROR(F37/$F$106,"") -> 0.0045146727 | O37: cited and landed | P37: =IF(F37=0,"",_xlfn.MINIFS(Sessions!$A:$A,Sessions!$D:$D,$A37)) -> 46246 | Q37: =IF(F37=0,"",_xlfn.MAXIFS(Sessions!$A:$A,Sessions!$D:$D,$A37)) -> 46247 | R37: =SUMIFS(Sessions!$J:$J,Sessions!$D:$D,$A37) -> 2
A38: https://ipfirstresponse.ipaustralia.gov.au/options/infringement-101-addressing-overseas-infringement | B38: /options/infringement-101-addressing-overseas-infringement | C38: options | E38: 41 | F38: =SUMIFS(Sessions!$I:$I,Sessions!$D:$D,$A38) -> 0 | G38: =SUMIFS(Sessions!$I:$I,Sessions!$D:$D,$A38,Sessions!$B:$B,"ChatGPT") -> 0 | H38: =SUMIFS(Sessions!$I:$I,Sessions!$D:$D,$A38,Sessions!$B:$B,"Claude") -> 0 | I38: =SUMIFS(Sessions!$I:$I,Sessions!$D:$D,$A38,Sessions!$B:$B,"Gemini") -> 0 | J38: =SUMIFS(Sessions!$I:$I,Sessions!$D:$D,$A38,Sessions!$B:$B,"Copilot") -> 0 | K38: =IFERROR(F38/E38,"") -> 0 | L38: =IFERROR(J38/E38,"") -> 0 | M38: =IFERROR(E38/$E$106,"") -> 0.0044555531 | N38: =IFERROR(F38/$F$106,"") -> 0 | O38: cited, no landings | P38: =IF(F38=0,"",_xlfn.MINIFS(Sessions!$A:$A,Sessions!$D:$D,$A38)) | Q38: =IF(F38=0,"",_xlfn.MAXIFS(Sessions!$A:$A,Sessions!$D:$D,$A38)) | R38: =SUMIFS(Sessions!$J:$J,Sessions!$D:$D,$A38) -> 0
A39: https://ipfirstresponse.ipaustralia.gov.au/tips-and-tricks-searching-existing-right | B39: /tips-and-tricks-searching-existing-right | C39: (top level) | D39: Tips and tricks for searching for an existing right | E39: 40 | F39: =SUMIFS(Sessions!$I:$I,Sessions!$D:$D,$A39) -> 14 | G39: =SUMIFS(Sessions!$I:$I,Sessions!$D:$D,$A39,Sessions!$B:$B,"ChatGPT") -> 13 | H39: =SUMIFS(Sessions!$I:$I,Sessions!$D:$D,$A39,Sessions!$B:$B,"Claude") -> 0 | I39: =SUMIFS(Sessions!$I:$I,Sessions!$D:$D,$A39,Sessions!$B:$B,"Gemini") -> 1 | J39: =SUMIFS(Sessions!$I:$I,Sessions!$D:$D,$A39,Sessions!$B:$B,"Copilot") -> 0 | K39: =IFERROR(F39/E39,"") -> 0.35 | L39: =IFERROR(J39/E39,"") -> 0 | M39: =IFERROR(E39/$E$106,"") -> 0.0043468811 | N39: =IFERROR(F39/$F$106,"") -> 0.031602709 | O39: cited and landed | P39: =IF(F39=0,"",_xlfn.MINIFS(Sessions!$A:$A,Sessions!$D:$D,$A39)) -> 46164 | Q39: =IF(F39=0,"",_xlfn.MAXIFS(Sessions!$A:$A,Sessions!$D:$D,$A39)) -> 46275 | R39: =SUMIFS(Sessions!$J:$J,Sessions!$D:$D,$A39) -> 14
A40: https://ipfirstresponse.ipaustralia.gov.au/options/what-ip-and-how-does-it-protect-me | B40: /options/what-ip-and-how-does-it-protect-me | C40: options | D40: What is IP and how does it protect me? | E40: 38 | F40: =SUMIFS(Sessions!$I:$I,Sessions!$D:$D,$A40) -> 5 | G40: =SUMIFS(Sessions!$I:$I,Sessions!$D:$D,$A40,Sessions!$B:$B,"ChatGPT") -> 5 | H40: =SUMIFS(Sessions!$I:$I,Sessions!$D:$D,$A40,Sessions!$B:$B,"Claude") -> 0 | I40: =SUMIFS(Sessions!$I:$I,Sessions!$D:$D,$A40,Sessions!$B:$B,"Gemini") -> 0 | J40: =SUMIFS(Sessions!$I:$I,Sessions!$D:$D,$A40,Sessions!$B:$B,"Copilot") -> 0 | K40: =IFERROR(F40/E40,"") -> 0.13157895 | L40: =IFERROR(J40/E40,"") -> 0 | M40: =IFERROR(E40/$E$106,"") -> 0.0041295371 | N40: =IFERROR(F40/$F$106,"") -> 0.011286682 | O40: cited and landed | P40: =IF(F40=0,"",_xlfn.MINIFS(Sessions!$A:$A,Sessions!$D:$D,$A40)) -> 46243 | Q40: =IF(F40=0,"",_xlfn.MAXIFS(Sessions!$A:$A,Sessions!$D:$D,$A40)) -> 46269 | R40: =SUMIFS(Sessions!$J:$J,Sessions!$D:$D,$A40) -> 4
...

Sheet Daily
A1: date | B1: year | C1: month | D1: ISO week | E1: week starting | F1: day | G1: weekend | H1: citations (Bing AI) | I1: cited pages | J1: sessions (all AI referrers) | K1: ChatGPT | L1: Claude | M1: Gemini | N1: Copilot | O1: CTR all referrers | P1: CTR Copilot only | Q1: source coverage
A2: 46156 | B2: 2026 | C2: May 2026 | D2: 20 | E2: 46153 | F2: Thu | G2: no | H2: 123 | I2: 15 | J2: =SUMIFS(Sessions!$I:$I,Sessions!$A:$A,$A2) -> 0 | K2: =SUMIFS(Sessions!$I:$I,Sessions!$A:$A,$A2,Sessions!$B:$B,"ChatGPT") -> 0 | L2: =SUMIFS(Sessions!$I:$I,Sessions!$A:$A,$A2,Sessions!$B:$B,"Claude") -> 0 | M2: =SUMIFS(Sessions!$I:$I,Sessions!$A:$A,$A2,Sessions!$B:$B,"Gemini") -> 0 | N2: =SUMIFS(Sessions!$I:$I,Sessions!$A:$A,$A2,Sessions!$B:$B,"Copilot") -> 0 | O2: =IFERROR(J2/H2,"") -> 0 | P2: =IFERROR(N2/H2,"") -> 0 | Q2: citations only
A3: 46157 | B3: 2026 | C3: May 2026 | D3: 20 | E3: 46153 | F3: Fri | G3: no | H3: 34 | I3: 9 | J3: =SUMIFS(Sessions!$I:$I,Sessions!$A:$A,$A3) -> 1 | K3: =SUMIFS(Sessions!$I:$I,Sessions!$A:$A,$A3,Sessions!$B:$B,"ChatGPT") -> 0 | L3: =SUMIFS(Sessions!$I:$I,Sessions!$A:$A,$A3,Sessions!$B:$B,"Claude") -> 1 | M3: =SUMIFS(Sessions!$I:$I,Sessions!$A:$A,$A3,Sessions!$B:$B,"Gemini") -> 0 | N3: =SUMIFS(Sessions!$I:$I,Sessions!$A:$A,$A3,Sessions!$B:$B,"Copilot") -> 0 | O3: =IFERROR(J3/H3,"") -> 0.029411765 | P3: =IFERROR(N3/H3,"") -> 0 | Q3: both
A4: 46158 | B4: 2026 | C4: May 2026 | D4: 20 | E4: 46153 | F4: Sat | G4: yes | H4: 23 | I4: 6 | J4: =SUMIFS(Sessions!$I:$I,Sessions!$A:$A,$A4) -> 1 | K4: =SUMIFS(Sessions!$I:$I,Sessions!$A:$A,$A4,Sessions!$B:$B,"ChatGPT") -> 1 | L4: =SUMIFS(Sessions!$I:$I,Sessions!$A:$A,$A4,Sessions!$B:$B,"Claude") -> 0 | M4: =SUMIFS(Sessions!$I:$I,Sessions!$A:$A,$A4,Sessions!$B:$B,"Gemini") -> 0 | N4: =SUMIFS(Sessions!$I:$I,Sessions!$A:$A,$A4,Sessions!$B:$B,"Copilot") -> 0 | O4: =IFERROR(J4/H4,"") -> 0.043478261 | P4: =IFERROR(N4/H4,"") -> 0 | Q4: both
A5: 46159 | B5: 2026 | C5: May 2026 | D5: 20 | E5: 46153 | F5: Sun | G5: yes | H5: 79 | I5: 14 | J5: =SUMIFS(Sessions!$I:$I,Sessions!$A:$A,$A5) -> 0 | K5: =SUMIFS(Sessions!$I:$I,Sessions!$A:$A,$A5,Sessions!$B:$B,"ChatGPT") -> 0 | L5: =SUMIFS(Sessions!$I:$I,Sessions!$A:$A,$A5,Sessions!$B:$B,"Claude") -> 0 | M5: =SUMIFS(Sessions!$I:$I,Sessions!$A:$A,$A5,Sessions!$B:$B,"Gemini") -> 0 | N5: =SUMIFS(Sessions!$I:$I,Sessions!$A:$A,$A5,Sessions!$B:$B,"Copilot") -> 0 | O5: =IFERROR(J5/H5,"") -> 0 | P5: =IFERROR(N5/H5,"") -> 0 | Q5: both
A6: 46160 | B6: 2026 | C6: May 2026 | D6: 21 | E6: 46160 | F6: Mon | G6: no | H6: 54 | I6: 15 | J6: =SUMIFS(Sessions!$I:$I,Sessions!$A:$A,$A6) -> 1 | K6: =SUMIFS(Sessions!$I:$I,Sessions!$A:$A,$A6,Sessions!$B:$B,"ChatGPT") -> 0 | L6: =SUMIFS(Sessions!$I:$I,Sessions!$A:$A,$A6,Sessions!$B:$B,"Claude") -> 1 | M6: =SUMIFS(Sessions!$I:$I,Sessions!$A:$A,$A6,Sessions!$B:$B,"Gemini") -> 0 | N6: =SUMIFS(Sessions!$I:$I,Sessions!$A:$A,$A6,Sessions!$B:$B,"Copilot") -> 0 | O6: =IFERROR(J6/H6,"") -> 0.018518519 | P6: =IFERROR(N6/H6,"") -> 0 | Q6: both
A7: 46161 | B7: 2026 | C7: May 2026 | D7: 21 | E7: 46160 | F7: Tue | G7: no | H7: 84 | I7: 14 | J7: =SUMIFS(Sessions!$I:$I,Sessions!$A:$A,$A7) -> 2 | K7: =SUMIFS(Sessions!$I:$I,Sessions!$A:$A,$A7,Sessions!$B:$B,"ChatGPT") -> 2 | L7: =SUMIFS(Sessions!$I:$I,Sessions!$A:$A,$A7,Sessions!$B:$B,"Claude") -> 0 | M7: =SUMIFS(Sessions!$I:$I,Sessions!$A:$A,$A7,Sessions!$B:$B,"Gemini") -> 0 | N7: =SUMIFS(Sessions!$I:$I,Sessions!$A:$A,$A7,Sessions!$B:$B,"Copilot") -> 0 | O7: =IFERROR(J7/H7,"") -> 0.023809524 | P7: =IFERROR(N7/H7,"") -> 0 | Q7: both
A8: 46162 | B8: 2026 | C8: May 2026 | D8: 21 | E8: 46160 | F8: Wed | G8: no | H8: 64 | I8: 9 | J8: =SUMIFS(Sessions!$I:$I,Sessions!$A:$A,$A8) -> 2 | K8: =SUMIFS(Sessions!$I:$I,Sessions!$A:$A,$A8,Sessions!$B:$B,"ChatGPT") -> 2 | L8: =SUMIFS(Sessions!$I:$I,Sessions!$A:$A,$A8,Sessions!$B:$B,"Claude") -> 0 | M8: =SUMIFS(Sessions!$I:$I,Sessions!$A:$A,$A8,Sessions!$B:$B,"Gemini") -> 0 | N8: =SUMIFS(Sessions!$I:$I,Sessions!$A:$A,$A8,Sessions!$B:$B,"Copilot") -> 0 | O8: =IFERROR(J8/H8,"") -> 0.03125 | P8: =IFERROR(N8/H8,"") -> 0 | Q8: both
A9: 46163 | B9: 2026 | C9: May 2026 | D9: 21 | E9: 46160 | F9: Thu | G9: no | H9: 74 | I9: 12 | J9: =SUMIFS(Sessions!$I:$I,Sessions!$A:$A,$A9) -> 3 | K9: =SUMIFS(Sessions!$I:$I,Sessions!$A:$A,$A9,Sessions!$B:$B,"ChatGPT") -> 3 | L9: =SUMIFS(Sessions!$I:$I,Sessions!$A:$A,$A9,Sessions!$B:$B,"Claude") -> 0 | M9: =SUMIFS(Sessions!$I:$I,Sessions!$A:$A,$A9,Sessions!$B:$B,"Gemini") -> 0 | N9: =SUMIFS(Sessions!$I:$I,Sessions!$A:$A,$A9,Sessions!$B:$B,"Copilot") -> 0 | O9: =IFERROR(J9/H9,"") -> 0.040540541 | P9: =IFERROR(N9/H9,"") -> 0 | Q9: both
A10: 46164 | B10: 2026 | C10: May 2026 | D10: 21 | E10: 46160 | F10: Fri | G10: no | H10: 28 | I10: 7 | J10: =SUMIFS(Sessions!$I:$I,Sessions!$A:$A,$A10) -> 2 | K10: =SUMIFS(Sessions!$I:$I,Sessions!$A:$A,$A10,Sessions!$B:$B,"ChatGPT") -> 1 | L10: =SUMIFS(Sessions!$I:$I,Sessions!$A:$A,$A10,Sessions!$B:$B,"Claude") -> 0 | M10: =SUMIFS(Sessions!$I:$I,Sessions!$A:$A,$A10,Sessions!$B:$B,"Gemini") -> 0 | N10: =SUMIFS(Sessions!$I:$I,Sessions!$A:$A,$A10,Sessions!$B:$B,"Copilot") -> 1 | O10: =IFERROR(J10/H10,"") -> 0.071428571 | P10: =IFERROR(N10/H10,"") -> 0.035714286 | Q10: both
A11: 46165 | B11: 2026 | C11: May 2026 | D11: 21 | E11: 46160 | F11: Sat | G11: yes | H11: 22 | I11: 6 | J11: =SUMIFS(Sessions!$I:$I,Sessions!$A:$A,$A11) -> 0 | K11: =SUMIFS(Sessions!$I:$I,Sessions!$A:$A,$A11,Sessions!$B:$B,"ChatGPT") -> 0 | L11: =SUMIFS(Sessions!$I:$I,Sessions!$A:$A,$A11,Sessions!$B:$B,"Claude") -> 0 | M11: =SUMIFS(Sessions!$I:$I,Sessions!$A:$A,$A11,Sessions!$B:$B,"Gemini") -> 0 | N11: =SUMIFS(Sessions!$I:$I,Sessions!$A:$A,$A11,Sessions!$B:$B,"Copilot") -> 0 | O11: =IFERROR(J11/H11,"") -> 0 | P11: =IFERROR(N11/H11,"") -> 0 | Q11: both
A12: 46166 | B12: 2026 | C12: May 2026 | D12: 21 | E12: 46160 | F12: Sun | G12: yes | H12: 23 | I12: 8 | J12: =SUMIFS(Sessions!$I:$I,Sessions!$A:$A,$A12) -> 0 | K12: =SUMIFS(Sessions!$I:$I,Sessions!$A:$A,$A12,Sessions!$B:$B,"ChatGPT") -> 0 | L12: =SUMIFS(Sessions!$I:$I,Sessions!$A:$A,$A12,Sessions!$B:$B,"Claude") -> 0 | M12: =SUMIFS(Sessions!$I:$I,Sessions!$A:$A,$A12,Sessions!$B:$B,"Gemini") -> 0 | N12: =SUMIFS(Sessions!$I:$I,Sessions!$A:$A,$A12,Sessions!$B:$B,"Copilot") -> 0 | O12: =IFERROR(J12/H12,"") -> 0 | P12: =IFERROR(N12/H12,"") -> 0 | Q12: both
A13: 46167 | B13: 2026 | C13: May 2026 | D13: 22 | E13: 46167 | F13: Mon | G13: no | H13: 78 | I13: 18 | J13: =SUMIFS(Sessions!$I:$I,Sessions!$A:$A,$A13) -> 2 | K13: =SUMIFS(Sessions!$I:$I,Sessions!$A:$A,$A13,Sessions!$B:$B,"ChatGPT") -> 1 | L13: =SUMIFS(Sessions!$I:$I,Sessions!$A:$A,$A13,Sessions!$B:$B,"Claude") -> 1 | M13: =SUMIFS(Sessions!$I:$I,Sessions!$A:$A,$A13,Sessions!$B:$B,"Gemini") -> 0 | N13: =SUMIFS(Sessions!$I:$I,Sessions!$A:$A,$A13,Sessions!$B:$B,"Copilot") -> 0 | O13: =IFERROR(J13/H13,"") -> 0.025641026 | P13: =IFERROR(N13/H13,"") -> 0 | Q13: both
... A119: 46273 | B119: 2026 | C119: Sep 2026 | D119: 37 | E119: 46272 | F119: Tue | G119: no | H119: 121 | I119: 19 | J119: =SUMIFS(Sessions!$I:$I,Sessions!$A:$A,$A119) -> 7 | K119: =SUMIFS(Sessions!$I:$I,Sessions!$A:$A,$A119,Sessions!$B:$B,"ChatGPT") -> 7 | L119: =SUMIFS(Sessions!$I:$I,Sessions!$A:$A,$A119,Sessions!$B:$B,"Claude") -> 0 | M119: =SUMIFS(Sessions!$I:$I,Sessions!$A:$A,$A119,Sessions!$B:$B,"Gemini") -> 0 | N119: =SUMIFS(Sessions!$I:$I,Sessions!$A:$A,$A119,Sessions!$B:$B,"Copilot") -> 0 | O119: =IFERROR(J119/H119,"") -> 0.05785124 | P119: =IFERROR(N119/H119,"") -> 0 | Q119: both
A120: 46274 | B120: 2026 | C120: Sep 2026 | D120: 37 | E120: 46272 | F120: Wed | G120: no | J120: =SUMIFS(Sessions!$I:$I,Sessions!$A:$A,$A120) -> 7 | K120: =SUMIFS(Sessions!$I:$I,Sessions!$A:$A,$A120,Sessions!$B:$B,"ChatGPT") -> 7 | L120: =SUMIFS(Sessions!$I:$I,Sessions!$A:$A,$A120,Sessions!$B:$B,"Claude") -> 0 | M120: =SUMIFS(Sessions!$I:$I,Sessions!$A:$A,$A120,Sessions!$B:$B,"Gemini") -> 0 | N120: =SUMIFS(Sessions!$I:$I,Sessions!$A:$A,$A120,Sessions!$B:$B,"Copilot") -> 0 | O120: =IFERROR(J120/H120,"") | P120: =IFERROR(N120/H120,"") | Q120: sessions only
A121: 46275 | B121: 2026 | C121: Sep 2026 | D121: 37 | E121: 46272 | F121: Thu | G121: no | J121: =SUMIFS(Sessions!$I:$I,Sessions!$A:$A,$A121) -> 11 | K121: =SUMIFS(Sessions!$I:$I,Sessions!$A:$A,$A121,Sessions!$B:$B,"ChatGPT") -> 11 | L121: =SUMIFS(Sessions!$I:$I,Sessions!$A:$A,$A121,Sessions!$B:$B,"Claude") -> 0 | M121: =SUMIFS(Sessions!$I:$I,Sessions!$A:$A,$A121,Sessions!$B:$B,"Gemini") -> 0 | N121: =SUMIFS(Sessions!$I:$I,Sessions!$A:$A,$A121,Sessions!$B:$B,"Copilot") -> 0 | O121: =IFERROR(J121/H121,"") | P121: =IFERROR(N121/H121,"") | Q121: sessions only
A122: 46276 | B122: 2026 | C122: Sep 2026 | D122: 37 | E122: 46272 | F122: Fri | G122: no | J122: =SUMIFS(Sessions!$I:$I,Sessions!$A:$A,$A122) -> 1 | K122: =SUMIFS(Sessions!$I:$I,Sessions!$A:$A,$A122,Sessions!$B:$B,"ChatGPT") -> 1 | L122: =SUMIFS(Sessions!$I:$I,Sessions!$A:$A,$A122,Sessions!$B:$B,"Claude") -> 0 | M122: =SUMIFS(Sessions!$I:$I,Sessions!$A:$A,$A122,Sessions!$B:$B,"Gemini") -> 0 | N122: =SUMIFS(Sessions!$I:$I,Sessions!$A:$A,$A122,Sessions!$B:$B,"Copilot") -> 0 | O122: =IFERROR(J122/H122,"") | P122: =IFERROR(N122/H122,"") | Q122: sessions only
A123: TOTAL (visible rows) | H123: =SUBTOTAL(109,H2:H122) -> 10465 | I123: =SUBTOTAL(101,I2:I122) -> 12.567797 | J123: =SUBTOTAL(109,J2:J122) -> 443 | K123: =SUBTOTAL(109,K2:K122) -> 401 | L123: =SUBTOTAL(109,L2:L122) -> 22 | M123: =SUBTOTAL(109,M2:M122) -> 17 | N123: =SUBTOTAL(109,N2:N122) -> 3 | O123: =IFERROR(J123/H123,"") -> 0.042331581 | P123: =IFERROR(N123/H123,"") -> 0.00028666985
A125: 'cited pages' is a daily count of distinct pages, so the total row shows its average rather than a sum. Days outside one source are left blank, not zero.

Sheet Weekly
A1: week starting | B1: week ending | C1: ISO week | D1: days in range | E1: citations (Bing AI) | F1: sessions (all AI referrers) | G1: ChatGPT | H1: Claude | I1: Gemini | J1: Copilot | K1: CTR (weekly totals) | L1: CTR (mean of daily CTRs) | M1: avg cited pages per day | N1: complete week
A2: 46153 | B2: 46159 | C2: 2026-W20 | D2: 4 | E2: =SUMIFS(Daily!$H:$H,Daily!$E:$E,$A2) -> 259 | F2: =SUMIFS(Daily!$J:$J,Daily!$E:$E,$A2) -> 2 | G2: =SUMIFS(Daily!$K:$K,Daily!$E:$E,$A2) -> 1 | H2: =SUMIFS(Daily!$L:$L,Daily!$E:$E,$A2) -> 1 | I2: =SUMIFS(Daily!$M:$M,Daily!$E:$E,$A2) -> 0 | J2: =SUMIFS(Daily!$N:$N,Daily!$E:$E,$A2) -> 0 | K2: =IFERROR(F2/E2,"") -> 0.0077220077 | L2: =IFERROR(AVERAGEIFS(Daily!$O:$O,Daily!$E:$E,$A2),"") -> 0.018222506 | M2: =IFERROR(AVERAGEIFS(Daily!$I:$I,Daily!$E:$E,$A2),"") -> 11 | N2: no (partial)
